<robot name="car">
<!-- base link -->
  <link name="base_link">
    <inertial>
      <origin xyz="0 0 0" rpy="0 0 0" />
      <mass value="230" />
      <inertia
        ixx="933.13"
        ixy="-170.64"
        ixz="3.9682"
        iyy="696.22"
        iyz="-49.966"
        izz="472.27" />
    </inertial>
    <visual>
      <origin xyz="0 0 0" rpy="0 0 0" />
      <geometry>
        <mesh filename="package://car/meshes/base_link.STL" />
      </geometry>
      <material name="">
        <color rgba="0.79216 0.81961 0.93333 1" />
      </material>
    </visual>
    <collision>
      <origin xyz="0 0 0" rpy="0 0 0" />
      <geometry>
        <mesh filename="package://car/meshes/base_link.STL" />
      </geometry>
    </collision>
  </link>

<!-- car wheels -->
  <joint name="FL_wheel_joint" type="continuous">
    <parent link="base_link"/>
    <child link="FL_wheel"/>
    <origin xyz="0.51686 -0.01596 0.24885" rpy="0 0 0" />
  </joint>
 <link
    name="FL_wheel">
    <inertial>
      <origin
        xyz="0 0 0"
        rpy="0 0 0" />
      <mass
        value="12.374" />
      <inertia
        ixx="4.6302E-13"
        ixy="-2.0404E-09"
        ixz="3.1895E-09"
        iyy="3.0962E-05"
        iyz="2.1018E-13"
        izz="3.0962E-05" />
    </inertial>
    <visual>
      <origin xyz="0 0 0" rpy="0 0 0" />
      <geometry>
        <mesh
          filename="package://car/meshes/FL_wheel.STL" />
      </geometry>
      <material
        name="">
        <color
          rgba="0.79216 0.81961 0.93333 1" />
      </material>
    </visual>
  </link>

<joint name="FR_wheel_joint" type="continuous">
   <parent link="base_link"/>
   <child link="FR_wheel"/>
   <origin xyz="-0.51686 -0.01596 0.24885" rpy="0 0 0" />
</joint>

  <link
    name="FR_wheel">
    <inertial>
      <origin
        xyz="0 0 0"
        rpy="0 0 0" />
      <mass
        value="12.374" />
      <inertia
        ixx="2.6076E-13"
        ixy="-1.525E-09"
        ixz="-2.3975E-09"
        iyy="3.0962E-05"
        iyz="-1.1809E-13"
        izz="3.0962E-05" />
    </inertial>
    <visual>
      <origin
        xyz="0 0 0"
        rpy="0 0 0" />
      <geometry>
        <mesh
          filename="package://car/meshes/FR_wheel.STL" />
      </geometry>
      <material
        name="">
        <color
          rgba="0.79216 0.81961 0.93333 1" />
      </material>
    </visual>
    <collision>
      <origin
        xyz="0 0 0"
        rpy="0 0 0" />
      <geometry>
        <mesh
          filename="package://car/meshes/FR_wheel.STL" />
      </geometry>
    </collision>
  </link>

<joint name="RL_wheel_joint" type="continuous">
   <parent link="base_link"/>
   <child link="RL_wheel"/>
   <origin xyz="0.51686 2.08596 0.24885" rpy="0 0 0" />
</joint>

<link name="RL_wheel">
    <inertial>
      <origin
        xyz="0 0 0"
        rpy="0 0 0" />
      <mass
        value="12.374" />
      <inertia
        ixx="2.8764E-14"
        ixy="5.0415E-10"
        ixz="-7.9777E-10"
        iyy="3.0962E-05"
        iyz="1.299E-14"
        izz="3.0962E-05" />
    </inertial>
    <visual>
      <origin
        xyz="0 0 0"
        rpy="0 0 0" />
      <geometry>
        <mesh
          filename="package://car/meshes/RL_wheel.STL" />
      </geometry>
      <material
        name="">
        <color
          rgba="0.79216 0.81961 0.93333 1" />
      </material>
    </visual>
  </link>

<joint name="RR_wheel_joint" type="continuous">
   <parent link="base_link"/>
   <child link="RR_wheel"/>
   <origin xyz="-0.51686 2.08596 0.24885" rpy="0 0 0" />
</joint>

  <link
    name="RR_wheel">
    <inertial>
      <origin
        xyz="0.51686 2.08596 0.24885"
        rpy="0 0 0" />
      <mass
        value="12.374" />
      <inertia
        ixx="7.1179E-15"
        ixy="2.5605E-10"
        ixz="3.9348E-10"
        iyy="3.0963E-05"
        iyz="-3.2539E-15"
        izz="3.0963E-05" />
    </inertial>
    <visual>
      <origin
        xyz="0 0 0"
        rpy="0 0 0" />
      <geometry>
        <mesh
          filename="package://car/meshes/RR_wheel.STL" />
      </geometry>
      <material
        name="">
        <color
          rgba="0.79216 0.81961 0.93333 1" />
      </material>
    </visual>
    <collision>
      <origin
        xyz="0 0 0"
        rpy="0 0 0" />
      <geometry>
        <mesh
          filename="package://car/meshes/RR_wheel.STL" />
      </geometry>
    </collision>
  </link>


<!-- Lidar -->
  <joint name="lidar_joint" type="fixed">
      <parent link="base_link"/>
      <child link="lidar_link"/>
      <origin xyz="0 1.381 1.22877" rpy="0 0 0" />
  </joint>
  <link name="lidar_link">
      <visual>
          <origin xyz="0 50 50" rpy="0 0 0"/>
          <geometry>
              <mesh filename="package://car/meshes/lidar.STL" />
          </geometry>
          <material name="light_grey">
              <color rgba="0.8 0.8 0.8 0.8"/>
          </material>
      </visual>
  </link>

<!-- Radar -->
  <joint name="radar_joint" type="fixed">
      <parent link="base_link"/>
      <child link="radar_link"/>
      <origin xyz="0 -0.380 0.68778" rpy="0 0 0" />
  </joint>
  <link name="radar_link">
      <visual>
          <origin xyz="0 50 50" rpy="0 0 0"/>
          <geometry>
              <mesh filename="package://car/meshes/lidar.STL" />
          </geometry>
          <material name="light_grey">
              <color rgba="0.8 0.8 0.8 0.8"/>
          </material>
      </visual>
  </link>



  <!-- Camera Center -->
  <joint name="zed_camera_center_joint" type="fixed">
      <parent link="base_link"/>
      <child link="zed_camera_center"/>
      <origin xyz="0 0.788 1.176" rpy="0 0 0" />
  </joint>
  <link name="zed_camera_center">
      <visual>
          <origin xyz="0 0 0" rpy="0 0 0"/>
          <geometry>
              <mesh filename="package://car/meshes/ZED.STL" />
          </geometry>
          <material name="light_grey">
              <color rgba="0.8 0.8 0.8 0.8"/>
          </material>
      </visual>
  </link>

<!-- Left Camera -->
  <joint name="zed_left_camera_joint" type="fixed">
    <parent link="zed_camera_center"/>
    <child link="zed_left_camera_frame"/>
    <origin xyz="0.06 0 0" rpy="0 0 0" />
  </joint>

  <link name="zed_left_camera_frame" />

  <joint name="zed_left_camera_optical_joint" type="fixed">
    <origin xyz="0 0 0" rpy="-1.57079632679 0.0 -1.57079632679"/>
    <parent link="zed_left_camera_frame"/>
    <child link="zed_left_camera_optical_frame"/>
  </joint>

  <link name="zed_left_camera_optical_frame"/>

<!-- Right Camera -->
  <joint name="zed_right_camera_joint" type="fixed">
    <parent link="zed_camera_center"/>
    <child link="zed_right_camera_frame"/>
    <origin xyz="-0.06 0 0" rpy="0 0 0" />
  </joint>

  <link name="zed_right_camera_frame" />

  <joint name="zed_right_camera_optical_joint" type="fixed">
    <origin xyz="0 0 0" rpy="-1.57079632679 0.0 -1.57079632679"/>
    <parent link="zed_right_camera_frame"/>
    <child link="zed_right_camera_optical_frame"/>
  </joint>

  <link name="zed_right_camera_optical_frame"/>

</robot>
